<?xml version="1.0"?>

<robot name="estanteria" xmlns:xacro="http://www.ros.org/wiki/xacro">
	
<xacro:property name="altura" value="2.1" />
<xacro:property name="ancho" value="0.35" />
<xacro:property name="largo" value="1" />

<link name="world" />

<joint name="estanteria" type="floating">
  <parent link="world"/>
  <child link="estanteria_link"/>
  <origin xyz="0 0 0" rpy="0 0 0" />
</joint>

<link name="estanteria_link">
  <visual>
    <geometry>
      <box size="${largo} ${ancho} 0.02" /> 
    </geometry>
    <origin rpy="0 0 0" xyz="0 0 ${0.02/2}" />
    <material name="wood">
		<color rgba="${205/255} ${133/255} ${63/255} 1" />
    </material>
  </visual>
  <collision>
    <origin rpy="0 0 0" xyz="0 0 ${0.02/2}" />
    <geometry>
      <box size="${largo} ${ancho} 0.02" />  
    </geometry>
  </collision>
  <inertial>
    <origin rpy="0 0 0" xyz="0 0 ${0.02/2}" />
    <mass value="1" />
      <inertia ixx="0.01" ixy="0.0" ixz="0.0" iyy="0.01" iyz="0.0" izz="0.01"/>  
  </inertial>
</link>

<xacro:macro name="lateral" params="id refx">
<joint name="lateral_${id}" type="fixed">
  <parent link="estanteria_link"/>
  <child link="lateral_${id}_link"/>
  <origin xyz="${refx*((largo/2)+(0.02/2))} 0 0" rpy="0 0 0" />
</joint>

<link name="lateral_${id}_link">
  <visual>
    <geometry>
      <box size="0.02 ${ancho} ${altura}" />
    </geometry>
    <origin rpy="0 0 0" xyz="0 0 ${altura/2}" />
      <material name="wood" />
  </visual>
  <collision>
    <origin rpy="0 0 0" xyz="0 0 ${altura/2}" />
    <geometry>
      <box size="0.02 ${ancho} ${altura}" />
    </geometry>
  </collision>
  <inertial>
    <origin rpy="0 0 0" xyz="0 0 ${altura/2}" />
    <mass value="2" />
      <inertia ixx="0.01" ixy="0.0" ixz="0.0" iyy="0.01" iyz="0.0" izz="0.01"/>  
  </inertial>
</link>
</xacro:macro>

<xacro:lateral id="1" refx="1" />
<xacro:lateral id="2" refx="-1" />

<xacro:macro name="basal" params="id refz">
<joint name="basal_${id}" type="fixed">
  <parent link="estanteria_link"/>
  <child link="basal_${id}_link"/>
  <origin xyz="0 0 ${refz*(altura/5)}" rpy="0 0 0" />
</joint>

<link name="basal_${id}_link">
  <visual>
    <geometry>
      <box size="${largo} ${ancho} 0.02" />    
    </geometry>
    <origin rpy="0 0 0" xyz="0 0 -${0.02/2}" />
      <material name="wood" />
  </visual>
  <collision>
    <origin rpy="0 0 0" xyz="0 0 -${0.02/2}" />
    <geometry>
      <box size="${largo} ${ancho} 0.02" />  
    </geometry>
  </collision>
  <inertial>
    <origin rpy="0 0 0" xyz="0 0 -${0.02/2}" />
    <mass value="1" />
      <inertia ixx="0.01" ixy="0.0" ixz="0.0" iyy="0.01" iyz="0.0" izz="0.01"/>  
  </inertial>
</link>
</xacro:macro>

<xacro:basal id="1" refz="1" />
<xacro:basal id="2" refz="2" />
<xacro:basal id="3" refz="3" />
<xacro:basal id="4" refz="4" />
<xacro:basal id="5" refz="5" />

<gazebo reference="estanteria_link">
  <material>Gazebo/Wood</material>
  <mu1>1</mu1>
  <mu2>1</mu2>
  <selfCollide>true</selfCollide>
  <turnGravityOff>false</turnGravityOff>  
</gazebo>

<xacro:macro name="gazebo_lateral" params="id">
<gazebo reference="lateral_${id}_link">
  <material>Gazebo/Wood</material>
  <mu1>1</mu1>
  <mu2>1</mu2>
  <selfCollide>true</selfCollide>
  <turnGravityOff>false</turnGravityOff>  
</gazebo>
</xacro:macro>

<xacro:gazebo_lateral id="1"/>
<xacro:gazebo_lateral id="2"/>

<xacro:macro name="gazebo_basal" params="id">
<gazebo reference="basal_${id}_link">
  <material>Gazebo/Wood</material>
  <mu1>1</mu1>
  <mu2>1</mu2>
  <selfCollide>true</selfCollide>
  <turnGravityOff>false</turnGravityOff>  
</gazebo>
</xacro:macro>

<xacro:gazebo_basal id="1"/>
<xacro:gazebo_basal id="2"/>
<xacro:gazebo_basal id="3"/>
<xacro:gazebo_basal id="4"/>
<xacro:gazebo_basal id="5"/>

</robot>
