<?xml version="1.0"?>

<robot name="frigo" xmlns:xacro="http://www.ros.org/wiki/xacro">
	
<xacro:property name="altura" value="1.8" />
<xacro:property name="ancho" value="0.6" />
<xacro:property name="largo" value="0.6" />

<link name="world" />

<joint name="frigo" type="floating">
  <parent link="world"/>
  <child link="frigo_link"/>
  <origin xyz="0 0 0" rpy="0 0 0" />
</joint>

<link name="frigo_link">
  <visual>
    <geometry>
      <box size="${largo} ${ancho} ${altura}" /> 
    </geometry>
    <origin rpy="0 0 0" xyz="0 0 ${altura/2}" />
    <material name="white">
		<color rgba="1 1 1 1" />
    </material>
  </visual>
  <collision>
    <origin rpy="0 0 0" xyz="0 0 ${altura/2}" />
    <geometry>
      <box size="${largo} ${ancho} ${altura}" />  
    </geometry>
  </collision>
  <inertial>
    <origin rpy="0 0 0" xyz="0 0 ${altura/2}" />
    <mass value="50" />
      <inertia ixx="5" ixy="0.0" ixz="0.0" iyy="5" iyz="0.0" izz="5"/>  
  </inertial>
</link>

<gazebo reference="frigo_link">
  <material>Gazebo/White</material>
  <mu1>1</mu1>
  <mu2>1</mu2>
  <selfCollide>true</selfCollide>
  <turnGravityOff>false</turnGravityOff>  
</gazebo>

</robot>
