<?xml version="1.0" ?>
<!-- =================================================================================== -->
<!-- |    This document was autogenerated by xacro from lata_amstel.xacro              | -->
<!-- |    EDITING THIS FILE BY HAND IS NOT RECOMMENDED                                 | -->
<!-- =================================================================================== -->
<robot name="lata" xmlns:xacro="http://www.ros.org/wiki/xacro">
  <link name="world"/>
  <joint name="lata" type="floating">
    <parent link="world"/>
    <child link="lata_link"/>
    <origin rpy="0 0 0" xyz="0 0 0"/>
  </joint>
  <link name="lata_link">
    <visual>
      <geometry>
        <cylinder length="0.1115" radius="0.0325"/>
      </geometry>
      <origin rpy="0 0 0" xyz="0 0 0.06275"/>
      <material name="red">
        <color rgba="1 0 0 1"/>
      </material>
    </visual>
    <collision>
      <origin rpy="0 0 0" xyz="0 0 0.06275"/>
      <geometry>
        <cylinder length="0.1115" radius="0.0325"/>
      </geometry>
    </collision>
    <inertial>
      <origin rpy="0 0 0" xyz="0 0 0.06275"/>
      <mass value="0.01"/>
      <inertia ixx="0.001" ixy="0.0" ixz="0.0" iyy="0.001" iyz="0.0" izz="0.001"/>
    </inertial>
  </link>
  <joint name="lata_top" type="fixed">
    <parent link="lata_link"/>
    <child link="lata_top_link"/>
    <origin rpy="0 0 0" xyz="0 0 0.1185"/>
  </joint>
  <link name="lata_top_link">
    <visual>
      <geometry>
        <cylinder length="0.0015" radius="0.0325"/>
      </geometry>
      <origin rpy="0 0 0" xyz="0 0 0.00075"/>
      <material name="grey">
        <color rgba="0.8 0.8 0.8 1"/>
      </material>
    </visual>
    <collision>
      <origin rpy="0 0 0" xyz="0 0 0.00075"/>
      <geometry>
        <cylinder length="0.0015" radius="0.0325"/>
      </geometry>
    </collision>
    <inertial>
      <origin rpy="0 0 0" xyz="0 0 0.00075"/>
      <mass value="0.001"/>
      <inertia ixx="0.0001" ixy="0.0" ixz="0.0" iyy="0.0001" iyz="0.0" izz="0.0001"/>
    </inertial>
  </link>
  <joint name="lata_bottom" type="fixed">
    <parent link="lata_link"/>
    <child link="lata_bottom_link"/>
    <origin rpy="0 0 0" xyz="0 0 0"/>
  </joint>
  <link name="lata_bottom_link">
    <visual>
      <geometry>
        <cylinder length="0.007" radius="0.0325"/>
      </geometry>
      <origin rpy="0 0 0" xyz="0 0 0.0035"/>
      <material name="grey">
        <color rgba="0.8 0.8 0.8 1"/>
      </material>
    </visual>
    <collision>
      <origin rpy="0 0 0" xyz="0 0 0.0035"/>
      <geometry>
        <cylinder length="0.007" radius="0.0325"/>
      </geometry>
    </collision>
    <inertial>
      <origin rpy="0 0 0" xyz="0 0 0.0035"/>
      <mass value="0.001"/>
      <inertia ixx="0.0001" ixy="0.0" ixz="0.0" iyy="0.0001" iyz="0.0" izz="0.0001"/>
    </inertial>
  </link>
  <gazebo reference="lata_link">
    <material>objetos_fer/Amstel</material>
    <mu1>10</mu1>
    <mu2>10</mu2>
    <selfCollide>true</selfCollide>
    <turnGravityOff>true</turnGravityOff>
  </gazebo>
  <gazebo reference="lata_top_link">
    <material>objetos_fer/Grey0</material>
    <mu1>10</mu1>
    <mu2>10</mu2>
    <selfCollide>true</selfCollide>
    <turnGravityOff>true</turnGravityOff>
  </gazebo>
  <gazebo reference="lata_bottom_link">
    <material>objetos_fer/Grey0</material>
    <mu1>10</mu1>
    <mu2>10</mu2>
    <selfCollide>true</selfCollide>
    <turnGravityOff>true</turnGravityOff>
  </gazebo>
</robot>
