<?xml version="1.0"?>

<robot name="lata" xmlns:xacro="http://www.ros.org/wiki/xacro">

<link name="world" />

<joint name="lata" type="floating">
  <parent link="world"/>
  <child link="lata_link"/>
  <origin xyz="0 0 0" rpy="0 0 0" />
</joint>

<link name="lata_link">
  <visual>
    <geometry>

      <cylinder radius="0.0325" length="0.1115" />    
    </geometry>
    <origin rpy="0 0 0" xyz="0 0 ${(0.1115/2)+0.007}" />
    <material name="red">
      <color rgba="1 0 0 1" />
    </material>
  </visual>
  <collision>
    <origin rpy="0 0 0" xyz="0 0 ${(0.1115/2)+0.007}" />
    <geometry>

      <cylinder radius="0.0325" length="0.1115" />
    </geometry>
  </collision>
  <inertial>
    <origin rpy="0 0 0" xyz="0 0 ${(0.1115/2)+0.007}" />
    <mass value="0.01" />
      <inertia ixx="0.001" ixy="0.0" ixz="0.0" iyy="0.001" iyz="0.0" izz="0.001"/>  
  </inertial>
</link>

<joint name="lata_top" type="fixed">
  <parent link="lata_link"/>
  <child link="lata_top_link"/>
  <origin xyz="0 0 0.1185" rpy="0 0 0" />
</joint>

<link name="lata_top_link">
  <visual>
    <geometry>
      <cylinder radius="0.0325" length="0.0015" />    
    </geometry>
    <origin rpy="0 0 0" xyz="0 0 ${0.0015/2}" />
    <material name="grey">
      <color rgba="0.8 0.8 0.8 1" />
    </material>
  </visual>
  <collision>
    <origin rpy="0 0 0" xyz="0 0 ${0.0015/2}" />
    <geometry>
      <cylinder radius="0.0325" length="0.0015" />
    </geometry>
  </collision>
  <inertial>
    <origin rpy="0 0 0" xyz="0 0 ${0.0015/2}" />
    <mass value="0.001" />
      <inertia ixx="0.0001" ixy="0.0" ixz="0.0" iyy="0.0001" iyz="0.0" izz="0.0001"/>  
  </inertial>
</link>

<joint name="lata_bottom" type="fixed">
  <parent link="lata_link"/>
  <child link="lata_bottom_link"/>
  <origin xyz="0 0 0" rpy="0 0 0" />
</joint>

<link name="lata_bottom_link">
  <visual>
    <geometry>
      <cylinder radius="0.0325" length="0.007" />    
    </geometry>
    <origin rpy="0 0 0" xyz="0 0 ${0.007/2}" />
    <material name="grey">
      <color rgba="0.8 0.8 0.8 1" />
    </material>
  </visual>
  <collision>
    <origin rpy="0 0 0" xyz="0 0 ${0.007/2}" />
    <geometry>
      <cylinder radius="0.0325" length="0.007" />
    </geometry>
  </collision>
  <inertial>
    <origin rpy="0 0 0" xyz="0 0 ${0.007/2}" />
    <mass value="0.001" />
      <inertia ixx="0.0001" ixy="0.0" ixz="0.0" iyy="0.0001" iyz="0.0" izz="0.0001"/>  
  </inertial>
</link>

<gazebo reference="lata_link">
  <material>objetos_fer/Cola</material>
  <mu1>10</mu1>
  <mu2>10</mu2>
  <selfCollide>true</selfCollide>
  <turnGravityOff>true</turnGravityOff>  
</gazebo>

<gazebo reference="lata_top_link">
  <material>objetos_fer/Grey0</material>
  <mu1>10</mu1>
  <mu2>10</mu2>
  <selfCollide>true</selfCollide>
  <turnGravityOff>true</turnGravityOff>  
</gazebo>

<gazebo reference="lata_bottom_link">
  <material>objetos_fer/Grey0</material>
  <mu1>10</mu1>
  <mu2>10</mu2>
  <selfCollide>true</selfCollide>
  <turnGravityOff>true</turnGravityOff>  
</gazebo>

</robot>
