<?xml version="1.0"?>

<robot name="mesa" xmlns:xacro="http://www.ros.org/wiki/xacro">
	
<xacro:property name="altura" value="0.71" />	

<link name="world" />

<joint name="mesa" type="floating">
  <parent link="world"/>
  <child link="mesa_link"/>
  <origin xyz="0 0 0" rpy="0 0 0" />
</joint>

<link name="mesa_link">
  <visual>
    <geometry>
      <box size="2 0.75 0.03" /> 
    </geometry>
    <origin rpy="0 0 0" xyz="0 0 ${(0.03/2)+altura}" />
      <material name="wood">
		<color rgba="${205/255} ${133/255} ${63/255} 1" />
    </material>
  </visual>
  <collision>
    <origin rpy="0 0 0" xyz="0 0 ${(0.03/2)+altura}" />
    <geometry>
      <box size="2 0.75 0.03" /> 
    </geometry>
  </collision>
  <inertial>
    <origin rpy="0 0 0" xyz="0 0 ${(0.03/2)+altura}" />
    <mass value="5" />
      <inertia ixx="0.1" ixy="0.0" ixz="0.0" iyy="0.1" iyz="0.0" izz="0.1"/>  
  </inertial>
</link>


<xacro:macro name="pata" params="id refx refy">
<joint name="pata_${id}" type="fixed">
  <parent link="mesa_link"/>
  <child link="pata_${id}_link"/>
  <origin xyz="${refx*((2/2)-0.045)} ${refy*((0.75/2)-0.045)} 0" rpy="0 0 0" />
</joint>

<link name="pata_${id}_link">
  <visual>
    <geometry>
      <cylinder radius="0.025" length="${altura}" />    
    </geometry>
    <origin rpy="0 0 0" xyz="0 0 ${0.71/2}" />
    <material name="black">
      <color rgba="0 0 0 1" />
    </material>
  </visual>
  <collision>
    <origin rpy="0 0 0" xyz="0 0 ${altura/2}" />
    <geometry>
      <cylinder radius="0.025" length="${altura}" /> 
    </geometry>
  </collision>
  <inertial>
    <origin rpy="0 0 0" xyz="0 0 ${altura/2}" />
    <mass value="3" />
      <inertia ixx="0.1" ixy="0.0" ixz="0.0" iyy="0.1" iyz="0.0" izz="0.1"/>  
  </inertial>
</link>
</xacro:macro>

<xacro:pata id="1" refx="1" refy="1"/>
<xacro:pata id="2" refx="1" refy="-1"/>
<xacro:pata id="3" refx="-1" refy="-1"/>
<xacro:pata id="4" refx="-1" refy="1"/>

<gazebo reference="mesa_link">
  <material>objetos_fer/LightWood</material>
  <mu1>10</mu1>
  <mu2>10</mu2>
  <selfCollide>true</selfCollide>
  <turnGravityOff>false</turnGravityOff>  
</gazebo>

<xacro:macro name="gazebo_pata" params="id">
<gazebo reference="pata_${id}_link">
  <material>objetos_fer/Black</material>
  <mu1>0.9</mu1>
  <mu2>0.9</mu2>
  <selfCollide>true</selfCollide>
  <turnGravityOff>false</turnGravityOff>  
</gazebo>
</xacro:macro>

<xacro:gazebo_pata id="1"/>
<xacro:gazebo_pata id="2"/>
<xacro:gazebo_pata id="3"/>
<xacro:gazebo_pata id="4"/>

</robot>
