<?xml version="1.0" ?>
<!-- =================================================================================== -->
<!-- |    This document was autogenerated by xacro from mesa.xacro                     | -->
<!-- |    EDITING THIS FILE BY HAND IS NOT RECOMMENDED                                 | -->
<!-- =================================================================================== -->
<robot name="mesa" xmlns:xacro="http://www.ros.org/wiki/xacro">
  <link name="world"/>
  <joint name="mesa" type="floating">
    <parent link="world"/>
    <child link="mesa_link"/>
    <origin rpy="0 0 0" xyz="0 0 0"/>
  </joint>
  <link name="mesa_link">
    <visual>
      <geometry>
        <box size="2 0.75 0.03"/>
      </geometry>
      <origin rpy="0 0 0" xyz="0 0 0.725"/>
      <material name="wood">
        <color rgba="0.803921568627 0.521568627451 0.247058823529 1"/>
      </material>
    </visual>
    <collision>
      <origin rpy="0 0 0" xyz="0 0 0.725"/>
      <geometry>
        <box size="2 0.75 0.03"/>
      </geometry>
    </collision>
    <inertial>
      <origin rpy="0 0 0" xyz="0 0 0.725"/>
      <mass value="5"/>
      <inertia ixx="0.1" ixy="0.0" ixz="0.0" iyy="0.1" iyz="0.0" izz="0.1"/>
    </inertial>
  </link>
  <joint name="pata_1" type="fixed">
    <parent link="mesa_link"/>
    <child link="pata_1_link"/>
    <origin rpy="0 0 0" xyz="0.955 0.33 0"/>
  </joint>
  <link name="pata_1_link">
    <visual>
      <geometry>
        <cylinder length="0.71" radius="0.025"/>
      </geometry>
      <origin rpy="0 0 0" xyz="0 0 0.355"/>
      <material name="black">
        <color rgba="0 0 0 1"/>
      </material>
    </visual>
    <collision>
      <origin rpy="0 0 0" xyz="0 0 0.355"/>
      <geometry>
        <cylinder length="0.71" radius="0.025"/>
      </geometry>
    </collision>
    <inertial>
      <origin rpy="0 0 0" xyz="0 0 0.355"/>
      <mass value="3"/>
      <inertia ixx="0.1" ixy="0.0" ixz="0.0" iyy="0.1" iyz="0.0" izz="0.1"/>
    </inertial>
  </link>
  <joint name="pata_2" type="fixed">
    <parent link="mesa_link"/>
    <child link="pata_2_link"/>
    <origin rpy="0 0 0" xyz="0.955 -0.33 0"/>
  </joint>
  <link name="pata_2_link">
    <visual>
      <geometry>
        <cylinder length="0.71" radius="0.025"/>
      </geometry>
      <origin rpy="0 0 0" xyz="0 0 0.355"/>
      <material name="black">
        <color rgba="0 0 0 1"/>
      </material>
    </visual>
    <collision>
      <origin rpy="0 0 0" xyz="0 0 0.355"/>
      <geometry>
        <cylinder length="0.71" radius="0.025"/>
      </geometry>
    </collision>
    <inertial>
      <origin rpy="0 0 0" xyz="0 0 0.355"/>
      <mass value="3"/>
      <inertia ixx="0.1" ixy="0.0" ixz="0.0" iyy="0.1" iyz="0.0" izz="0.1"/>
    </inertial>
  </link>
  <joint name="pata_3" type="fixed">
    <parent link="mesa_link"/>
    <child link="pata_3_link"/>
    <origin rpy="0 0 0" xyz="-0.955 -0.33 0"/>
  </joint>
  <link name="pata_3_link">
    <visual>
      <geometry>
        <cylinder length="0.71" radius="0.025"/>
      </geometry>
      <origin rpy="0 0 0" xyz="0 0 0.355"/>
      <material name="black">
        <color rgba="0 0 0 1"/>
      </material>
    </visual>
    <collision>
      <origin rpy="0 0 0" xyz="0 0 0.355"/>
      <geometry>
        <cylinder length="0.71" radius="0.025"/>
      </geometry>
    </collision>
    <inertial>
      <origin rpy="0 0 0" xyz="0 0 0.355"/>
      <mass value="3"/>
      <inertia ixx="0.1" ixy="0.0" ixz="0.0" iyy="0.1" iyz="0.0" izz="0.1"/>
    </inertial>
  </link>
  <joint name="pata_4" type="fixed">
    <parent link="mesa_link"/>
    <child link="pata_4_link"/>
    <origin rpy="0 0 0" xyz="-0.955 0.33 0"/>
  </joint>
  <link name="pata_4_link">
    <visual>
      <geometry>
        <cylinder length="0.71" radius="0.025"/>
      </geometry>
      <origin rpy="0 0 0" xyz="0 0 0.355"/>
      <material name="black">
        <color rgba="0 0 0 1"/>
      </material>
    </visual>
    <collision>
      <origin rpy="0 0 0" xyz="0 0 0.355"/>
      <geometry>
        <cylinder length="0.71" radius="0.025"/>
      </geometry>
    </collision>
    <inertial>
      <origin rpy="0 0 0" xyz="0 0 0.355"/>
      <mass value="3"/>
      <inertia ixx="0.1" ixy="0.0" ixz="0.0" iyy="0.1" iyz="0.0" izz="0.1"/>
    </inertial>
  </link>
  <gazebo reference="mesa_link">
    <material>objetos_fer/LightWood</material>
    <mu1>10</mu1>
    <mu2>10</mu2>
    <selfCollide>true</selfCollide>
    <turnGravityOff>false</turnGravityOff>
  </gazebo>
  <gazebo reference="pata_1_link">
    <material>objetos_fer/Black</material>
    <mu1>0.9</mu1>
    <mu2>0.9</mu2>
    <selfCollide>true</selfCollide>
    <turnGravityOff>false</turnGravityOff>
  </gazebo>
  <gazebo reference="pata_2_link">
    <material>objetos_fer/Black</material>
    <mu1>0.9</mu1>
    <mu2>0.9</mu2>
    <selfCollide>true</selfCollide>
    <turnGravityOff>false</turnGravityOff>
  </gazebo>
  <gazebo reference="pata_3_link">
    <material>objetos_fer/Black</material>
    <mu1>0.9</mu1>
    <mu2>0.9</mu2>
    <selfCollide>true</selfCollide>
    <turnGravityOff>false</turnGravityOff>
  </gazebo>
  <gazebo reference="pata_4_link">
    <material>objetos_fer/Black</material>
    <mu1>0.9</mu1>
    <mu2>0.9</mu2>
    <selfCollide>true</selfCollide>
    <turnGravityOff>false</turnGravityOff>
  </gazebo>
</robot>

