<?xml version="1.0"?>

<robot name="cama" xmlns:xacro="http://www.ros.org/wiki/xacro">
	
<xacro:property name="altura" value="0.4" />
<xacro:property name="ancho" value="1.5" />
<xacro:property name="largo" value="2.1" />

<link name="world" />

<joint name="cama" type="floating">
  <parent link="world"/>
  <child link="cama_link"/>
  <origin xyz="0 0 0" rpy="0 0 0" />
</joint>

<link name="cama_link">
  <visual>
    <geometry>
      <box size="${largo} ${ancho} ${altura}" /> 
    </geometry>
    <origin rpy="0 0 0" xyz="0 0 ${altura/2}" />
    <material name="white">
		<color rgba="1 1 1 1" />
    </material>
  </visual>
  <collision>
    <origin rpy="0 0 0" xyz="0 0 ${altura/2}" />
    <geometry>
      <box size="${largo} ${ancho} ${altura}" />  
    </geometry>
  </collision>
  <inertial>
    <origin rpy="0 0 0" xyz="0 0 ${altura/2}" />
    <mass value="50" />
      <inertia ixx="10" ixy="0.0" ixz="0.0" iyy="10" iyz="0.0" izz="10"/>  
  </inertial>
</link>

<joint name="almohada" type="fixed">
  <parent link="cama_link"/>
  <child link="almohada_link"/>
  <origin xyz="${(largo/2)-(0.3/2)} 0 ${altura}" rpy="0 0 0" />
</joint>

<link name="almohada_link">
  <visual>
    <geometry>
      <box size="0.3 ${ancho} 0.1" /> 
    </geometry>
    <origin rpy="0 0 0" xyz="0 0 ${0.1/2}" />
    <material name="white">
		<color rgba="1 1 1 1" />
    </material>
  </visual>
  <collision>
    <origin rpy="0 0 0" xyz="0 0 ${0.1/2}" />
    <geometry>
      <box size="0.3 ${ancho} 0.1" />  
    </geometry>
  </collision>
  <inertial>
    <origin rpy="0 0 0" xyz="0 0 ${0.1/2}" />
    <mass value="1" />
      <inertia ixx="0.1" ixy="0.0" ixz="0.0" iyy="0.1" iyz="0.0" izz="0.1"/>  
  </inertial>
</link>

<gazebo reference="cama_link">
  <material>Gazebo/White</material>
  <mu1>1</mu1>
  <mu2>1</mu2>
  <selfCollide>true</selfCollide>
  <turnGravityOff>false</turnGravityOff>  
</gazebo>

<gazebo reference="almohada_link">
  <material>Gazebo/White</material>
  <mu1>1</mu1>
  <mu2>1</mu2>
  <selfCollide>true</selfCollide>
  <turnGravityOff>false</turnGravityOff>  
</gazebo>

</robot>
