<?xml version="1.0"?>

<robot name="mesa_salon" xmlns:xacro="http://www.ros.org/wiki/xacro">
	
<xacro:property name="altura" value="0.4" />
<xacro:property name="ancho" value="0.55" />
<xacro:property name="largo" value="0.9" />

<link name="world" />

<joint name="mesa" type="floating">
  <parent link="world"/>
  <child link="mesa_link"/>
  <origin xyz="0 0 0" rpy="0 0 0" />
</joint>

<link name="mesa_link">
  <visual>
    <geometry>
      <box size="${largo} ${ancho} 0.03" /> 
    </geometry>
    <origin rpy="0 0 0" xyz="0 0 ${(0.03/2)+altura}" />
      <material name="wood">
		<color rgba="${205/255} ${133/255} ${63/255} 1" />
    </material>
  </visual>
  <collision>
    <origin rpy="0 0 0" xyz="0 0 ${(0.03/2)+altura}" />
    <geometry>
      <box size="${largo} ${ancho} 0.03" /> 
    </geometry>
  </collision>
  <inertial>
    <origin rpy="0 0 0" xyz="0 0 ${(0.03/2)+altura}" />
    <mass value="2" />
      <inertia ixx="0.1" ixy="0.0" ixz="0.0" iyy="0.1" iyz="0.0" izz="0.1"/>  
  </inertial>
</link>


<xacro:macro name="pata" params="id refx refy">
<joint name="pata_${id}" type="fixed">
  <parent link="mesa_link"/>
  <child link="pata_${id}_link"/>
  <origin xyz="${refx*((largo/2)-0.03)} ${refy*((ancho/2)-0.03)} 0" rpy="0 0 0" />
</joint>

<link name="pata_${id}_link">
  <visual>
    <geometry>
      <box size="0.06 0.06 ${altura}" />    
    </geometry>
    <origin rpy="0 0 0" xyz="0 0 ${altura/2}" />
    <material name="black">
      <color rgba="0 0 0 1" />
    </material>
  </visual>
  <collision>
    <origin rpy="0 0 0" xyz="0 0 ${altura/2}" />
    <geometry>
      <box size="0.06 0.06 ${altura}" /> 
    </geometry>
  </collision>
  <inertial>
    <origin rpy="0 0 0" xyz="0 0 ${altura/2}" />
    <mass value="0.5" />
      <inertia ixx="0.1" ixy="0.0" ixz="0.0" iyy="0.1" iyz="0.0" izz="0.1"/>  
  </inertial>
</link>
</xacro:macro>

<xacro:pata id="1" refx="1" refy="1"/>
<xacro:pata id="2" refx="1" refy="-1"/>
<xacro:pata id="3" refx="-1" refy="-1"/>
<xacro:pata id="4" refx="-1" refy="1"/>

<gazebo reference="mesa_link">
  <material>Gazebo/Wood</material>
  <mu1>1</mu1>
  <mu2>1</mu2>
  <selfCollide>true</selfCollide>
  <turnGravityOff>false</turnGravityOff>  
</gazebo>

<xacro:macro name="gazebo_pata" params="id">
<gazebo reference="pata_${id}_link">
  <material>Gazebo/Wood</material>
  <mu1>1</mu1>
  <mu2>1</mu2>
  <selfCollide>true</selfCollide>
  <turnGravityOff>false</turnGravityOff>  
</gazebo>
</xacro:macro>

<xacro:gazebo_pata id="1"/>
<xacro:gazebo_pata id="2"/>
<xacro:gazebo_pata id="3"/>
<xacro:gazebo_pata id="4"/>

</robot>
